Workbook

Sheet Instructions
A1: MS Excel Practical Exam
A2: Total Questions: 30
A3: Difficulty Level: Medium
A4: Syllabus: Formulas, Logical Functions, Lookups, INDEX-MATCH, Pivot Tables & Charts, Data Analysis
A5: Attempt all questions using appropriate Excel tools/functions.

Sheet Sales_Data
A1: Order_ID | B1: Region | C1: Salesperson | D1: Product | E1: Quantity | F1: Unit_Price | G1: Sales_Date
A2: 301 | B2: North | C2: Amit | D2: Laptop | E2: 2 | F2: 45000 | G2: 05-01-2025
A3: 302 | B3: South | C3: Riya | D3: Mobile | E3: 5 | F3: 15000 | G3: 07-01-2025
A4: 303 | B4: East | C4: Kunal | D4: Tablet | E4: 3 | F4: 18000 | G4: 10-01-2025
A5: 304 | B5: West | C5: Neha | D5: Laptop | E5: 1 | F5: 45000 | G5: 12-01-2025
A6: 305 | B6: North | C6: Amit | D6: Mobile | E6: 4 | F6: 15000 | G6: 15-01-2025
A7: 306 | B7: South | C7: Riya | D7: Laptop | E7: 2 | F7: 45000 | G7: 18-01-2025

Sheet Product_Master
A1: Product | B1: Category | C1: GST_%
A2: Laptop | B2: Electronics | C2: 18
A3: Mobile | B3: Electronics | C3: 12
A4: Tablet | B4: Electronics | C4: 12

Sheet Sheet5
A3: Row Labels | B3: Sum of Excel
A4: Arjun | B4: 72
A5: Pooja | B5: 94
A6: Rahul | B6: 85
A7: Sneha | B7: 90
A8: Vikas | B8: 58
A9: Grand Total | B9: 399

Sheet Student_Marks
A1: Student_ID | B1: Name | C1: Maths | D1: Statistics | E1: Excel | F1: Attendance_% | G1: average
A2: 1 | B2: Rahul | C2: 78 | D2: 82 | E2: 85 | F2: 92 | G2: =AVERAGE(A2:F2) -> 67.6
A3: 2 | B3: Sneha | C3: 88 | D3: 91 | E3: 90 | F3: 96 | G3: =AVERAGE(A3:F3) -> 73.4
A4: 3 | B4: Arjun | C4: 65 | D4: 70 | E4: 72 | F4: 85 | G4: =AVERAGE(A4:F4) -> 59
A5: 4 | B5: Pooja | C5: 92 | D5: 89 | E5: 94 | F5: 98 | G5: =AVERAGE(A5:F5) -> 75.4
A6: 5 | B6: Vikas | C6: 55 | D6: 60 | E6: 58 | F6: 80 | G6: =AVERAGE(A6:F6) -> 51.6
B10: students | C10: eligible or not
B11: Rahul
B12: Sneha
B13: Arjun
B14: Pooja
B15: Vikas

Sheet Questions
A1: 1. Calculate Total Sales for each order (Quantity × Unit_Price). | J1: 2
A2: 2. Calculate GST Amount using VLOOKUP from Product_Master. | J2: 2
A3: 3. Find Final Amount payable (Total Sales + GST). | J3: 2
A4: 4. Find Grand Total of Final Amount. | J4: 2
A5: 5. Count total number of orders using COUNTA. | J5: 2
A6: 6. Find Region-wise total sales using SUMIF. | J6: 2
A8: 7. Use IF to classify Quantity as High (>3) or Low (<=3). | J8: 2
A9: 8. Find the maximum and minimum Final Amount. | J9: 2
A10: 9. Extract month name from Sales_Date. | J10: 2
A11: 10. Sort Sales_Data by Final Amount (Descending). | J11: 2
A12: 11. Use INDEX-MATCH to fetch Product Category. | J12: 2
A13: 12. Calculate average marks of each student. | J13: 2
... A59: 20. Find Median of Statistics marks. | J59: 2
B60: =MEDIAN(Student_Marks!B2,Student_Marks!D2) -> 82
A62: 21. Find Standard Deviation of Excel marks. | J62: 2
A63: 22. Use CONCAT to combine Student_ID and Name. | J63: 2
A70: 23. Use LEFT function to extract first 2 letters of Salesperson name. | J70: 2
A71: 24. Apply Conditional Formatting to highlight Final Amount > 60000. | J71: 2
A72: 25. Filter orders where Product is Laptop and Quantity > 1. | J72: 2
A73: 26. Use COUNTIFS to count Laptop orders in North region. | J73: 2
A74: 27. Use ROUND to round Unit_Price to nearest thousand. | J74: 2
A75: 28. Remove duplicate records if present. | J75: 2
A76: 29. Freeze top row in Sales_Data sheet. | J76: 2
A77: 30. Protect the Student_Marks sheet. | J77: 2
J79: =SUM(J1:J77) -> 60

Sheet Answers
A1: 1
A2: order | B2: sales
A3: 301 | B3: =VLOOKUP(A3,Sales_Data!A1:G7,5,0) -> 2
A4: 302 | B4: =VLOOKUP(A4,Sales_Data!A2:G8,5,0) -> 5
A5: 303 | B5: =VLOOKUP(A5,Sales_Data!A3:G9,5,0) -> 3
A6: 304 | B6: =VLOOKUP(A6,Sales_Data!A4:G10,5,0) -> 1
A7: 305 | B7: =VLOOKUP(A7,Sales_Data!A5:G11,5,0) -> 4
A8: 306 | B8: =VLOOKUP(A8,Sales_Data!A6:G12,5,0) -> 2
A10: 2
A11: product | B11: gst
A12: laptop | B12: =VLOOKUP(A12,Product_Master!A1:C4,3,0) -> 18
A14: 3
A20: 16
A21: Row Labels | B21: Sum of Unit_Price | C21: Sum of Quantity
A22: Laptop | B22: 135000 | C22: 5
A23: Mobile | B23: 30000 | C23: 9
A24: Tablet | B24: 18000 | C24: 3
A25: Grand Total | B25: 183000 | C25: 17
A28: 17
A29: Row Labels | B29: Sum of Quantity | C29: Sum of Unit_Price
A30: East | B30: 3 | C30: 18000
A31: North | B31: 6 | C31: 60000
A32: South | B32: 7 | C32: 60000
A33: West | B33: 1 | C33: 45000
A34: Grand Total | B34: 17 | C34: 183000
A37: 18
A38: Row Labels | B38: Sum of Unit_Price | C38: Sum of Quantity
A39: Laptop | B39: 135000 | C39: 5
A40: Mobile | B40: 30000 | C40: 9
A41: Tablet | B41: 18000 | C41: 3
A42: Grand Total | B42: 183000 | C42: 17
A45: 19
A59: 20
A60: 22
A61: =_xlfn.CONCAT(Student_Marks!A2,Student_Marks!B2) -> 1Rahul
A62: =_xlfn.CONCAT(Student_Marks!A3,Student_Marks!B3) -> 2Sneha
A63: =_xlfn.CONCAT(Student_Marks!A4,Student_Marks!B4) -> 3Arjun
A64: =_xlfn.CONCAT(Student_Marks!A5,Student_Marks!B5) -> 4Pooja
A65: =_xlfn.CONCAT(Student_Marks!A6,Student_Marks!B6) -> 5Vikas
A67: 12
...
